WARNING  django.request:log.py:248 Not Found: /phenotypes/PH1/detail/
WARNING  django.request:log.py:248 The request's session was deleted before the request completed. The user may have logged out in a concurrent request, for example.: /favicon.ico
Traceback (most recent call last):
  File "/opt/hostedtoolcache/Python/3.11.11/x64/lib/python3.11/site-packages/django/contrib/sessions/backends/db.py", line 127, in save
    obj.save(
  File "/opt/hostedtoolcache/Python/3.11.11/x64/lib/python3.11/site-packages/django/db/models/base.py", line 891, in save
    self.save_base(
  File "/opt/hostedtoolcache/Python/3.11.11/x64/lib/python3.11/site-packages/django/db/models/base.py", line 997, in save_base
    updated = self._save_table(
              ^^^^^^^^^^^^^^^^^
  File "/opt/hostedtoolcache/Python/3.11.11/x64/lib/python3.11/site-packages/django/db/models/base.py", line 1133, in _save_table
    raise DatabaseError("Forced update did not affect any rows.")
django.db.utils.DatabaseError: Forced update did not affect any rows.

During handling of the above exception, another exception occurred:

Traceback (most recent call last):
  File "/opt/hostedtoolcache/Python/3.11.11/x64/lib/python3.11/site-packages/django/contrib/sessions/middleware.py", line 59, in process_response
    request.session.save()
  File "/opt/hostedtoolcache/Python/3.11.11/x64/lib/python3.11/site-packages/django/contrib/sessions/backends/db.py", line 136, in save
    raise UpdateError
django.contrib.sessions.backends.base.UpdateError

During handling of the above exception, another exception occurred:

Traceback (most recent call last):
  File "/opt/hostedtoolcache/Python/3.11.11/x64/lib/python3.11/site-packages/django/core/handlers/exception.py", line 55, in inner
    response = get_response(request)
               ^^^^^^^^^^^^^^^^^^^^^
  File "/opt/hostedtoolcache/Python/3.11.11/x64/lib/python3.11/site-packages/django/utils/deprecation.py", line 131, in __call__
    response = self.process_response(request, response)
               ^^^^^^^^^^^^^^^^^^^^^^^^^^^^^^^^^^^^^^^^
  File "/opt/hostedtoolcache/Python/3.11.11/x64/lib/python3.11/site-packages/django/contrib/sessions/middleware.py", line 61, in process_response
    raise SessionInterrupted(
django.contrib.sessions.exceptions.SessionInterrupted: The request's session was deleted before the request completed. The user may have logged out in a concurrent request, for example.